<mujoco model="pendulum">
  <include file="./visual.xml"/>
  <include file="./skybox.xml"/>
  <include file="./materials.xml"/>
    
  <option timestep="0.001" integrator="RK4" gravity="0 0 -9.81">
    <flag contact="disable" energy="enable"/>
  </option>

  <worldbody>
    <light name="light" pos="0 0 0"/>
    <geom name="floor" size="2 2 .2" type="plane" material="grid"/>
    
    <body name="pole" pos="0 0 1.5">
      <joint name="hinge" type="hinge" axis="0 1 0" damping="0.1" frictionloss="0.2"/>
      
      <!-- 1번 링크: 질량 중심을 링크의 중간(0.125)으로 조정 & 이너시아 수정 -->
      <inertial pos="0.125 0 0" euler="0 0 0" mass="1.017"
                diaginertia="1.5679e-04 0.001375 0.001425"/>

      <geom name="pole" material="self" type="capsule" fromto="0 0 0 0.25 0 0" size="0.02"/>
      <geom name="mass" material="effector" type="sphere" pos="0.25 0 0" size="0.05" mass="1"/>

      <body name="pole2" pos="0.25 0 0">
        <joint name="hinge2" type="hinge" axis="0 1 0" damping="0.1" frictionloss="0.2"/>
        
        <!-- 2번 링크: 질량 중심을 링크의 중간(0.125)으로 조정 & 이너시아 수정 -->
        <inertial pos="0.125 0 0" euler="0 0 0" mass="0.2"
                  diaginertia="1.5789e-05 1.8739e-04 2.0079e-04"/>

        <geom name="pole2" material="self" type="capsule" fromto="0 0 0 0.25 0 0" size="0.02"/>
        <geom name="mass2" material="effector" type="sphere" pos="0.25 0 0" size="0.05" mass="1"/>
      </body>
    </body>
  </worldbody>

  <actuator>
    <motor name="joint1" joint="hinge" gear="1" ctrlrange="-100 100" ctrllimited="true"/>
    <motor name="joint2" joint="hinge2" gear="1" ctrlrange="-100 100" ctrllimited="true"/>
  </actuator>

  <keyframe>
    <key name="start" qpos="0.7854 1.5708" qvel = "0 0"/>
  </keyframe>


</mujoco>
